Workbook
Name SegmentaciónDeDatos_CAT.: #REF!
Name SegmentaciónDeDatos_CAT.1: #REF!
Name SegmentaciónDeDatos_CAT.2: #REF!
Name SegmentaciónDeDatos_COMP.: #REF!
Name SegmentaciónDeDatos_COMP.1: #REF!
Name SegmentaciónDeDatos_COMP.2: #REF!
Name SegmentaciónDeDatos_COMP.3: #REF!
Name SegmentaciónDeDatos_FECHA_ENTRADA: #REF!
Name SegmentaciónDeDatos_FECHA_ENTRADA1: #REF!
Name SegmentaciónDeDatos_FECHA_ENTRADA2: #REF!
Name SegmentaciónDeDatos_FECHA_SALIDA: #REF!
Name SegmentaciónDeDatos_FECHA_SALIDA1: #REF!
Name SegmentaciónDeDatos_FECHA_SALIDA2: #REF!
Name SegmentaciónDeDatos_UBIC.: #REF!
Name SegmentaciónDeDatos_UBIC.1: #REF!
Name SegmentaciónDeDatos_UBIC.2: #REF!

Sheet CONCENTRADO
A1: Columna 1 | B1: Columna 2 | C1: Columna 3 | D1: Columna 4 | E1: Columna 5 | F1: Columna 6 | G1: Columna 7
A2: CÓDIGO | B2: COMP. | C2: CAT. | D2: FAM. | E2: CONS. | F2: DESCRIPCIÓN | G2: UM
A3: =CONCATENATE(CONCENTRADO!$B3,CONCENTRADO!$C3,CONCENTRADO!$D3,CONCENTRADO!$E3) -> GCN0070001 | B3: G | C3: CN | D3: 007 | E3: 0001 | F3: Rodamiento Taza H-913810 Timken | G3: Pz
A4: =CONCATENATE(CONCENTRADO!$B4,CONCENTRADO!$C4,CONCENTRADO!$D4,CONCENTRADO!$E4) -> GCN0070002 | B4: G | C4: CN | D4: 007 | E4: 0002 | F4: Rodamiento 6304-Zzc3E | G4: Pz
A5: =CONCATENATE(CONCENTRADO!$B5,CONCENTRADO!$C5,CONCENTRADO!$D5,CONCENTRADO!$E5) -> GCN0070003 | B5: G | C5: CN | D5: 007 | E5: 0003 | F5: Taza 493 Mca Timken | G5: Pz
A6: =CONCATENATE(CONCENTRADO!$B6,CONCENTRADO!$C6,CONCENTRADO!$D6,CONCENTRADO!$E6) -> GCN0070004 | B6: G | C6: CN | D6: 007 | E6: 0004 | F6: Reten Hidraulico / Neumatico Skf #504272 | G6: Pz
A7: =CONCATENATE(CONCENTRADO!$B7,CONCENTRADO!$C7,CONCENTRADO!$D7,CONCENTRADO!$E7) -> GCN0070005 | B7: G | C7: CN | D7: 007 | E7: 0005 | F7: Rodamiento 6204-2Rsh/C3 Skf | G7: Pz
A8: =CONCATENATE(CONCENTRADO!$B8,CONCENTRADO!$C8,CONCENTRADO!$D8,CONCENTRADO!$E8) -> GCN0070006 | B8: G | C8: CN | D8: 007 | E8: 0006 | F8: Reten Metalico 1.3975X1.8755X.2875 | G8: Pz
A9: =CONCATENATE(CONCENTRADO!$B9,CONCENTRADO!$C9,CONCENTRADO!$D9,CONCENTRADO!$E9) -> GCN0070007 | B9: G | C9: CN | D9: 007 | E9: 0007 | F9: Reten 17211 Ptc Dichtomatik | G9: Pz
A10: =CONCATENATE(CONCENTRADO!$B10,CONCENTRADO!$C10,CONCENTRADO!$D10,CONCENTRADO!$E10) -> GCN0070008 | B10: G | C10: CN | D10: 007 | E10: 0008 | F10: 3.935X4.625X.365 Reten Metalico Nitrilo | G10: Pz
A11: =CONCATENATE(CONCENTRADO!$B11,CONCENTRADO!$C11,CONCENTRADO!$D11,CONCENTRADO!$E11) -> GCN0070009 | B11: G | C11: CN | D11: 007 | E11: 0009 | F11: Balero Axial De Bolas 7304-B- Xl-Tvp- Fag | G11: Pz
A12: =CONCATENATE(CONCENTRADO!$B12,CONCENTRADO!$C12,CONCENTRADO!$D12,CONCENTRADO!$E12) -> GCN0070010 | B12: G | C12: CN | D12: 007 | E12: 0010 | F12: Sello 9850 Skf | G12: Pz
A13: =CONCATENATE(CONCENTRADO!$B13,CONCENTRADO!$C13,CONCENTRADO!$D13,CONCENTRADO!$E13) -> GCN0070011 | B13: G | C13: CN | D13: 007 | E13: 0011 | F13: Rodamiento Cono H-913840 Timken | G13: Pz
A14: =CONCATENATE(CONCENTRADO!$B14,CONCENTRADO!$C14,CONCENTRADO!$D14,CONCENTRADO!$E14) -> GCN0070012 | B14: G | C14: CN | D14: 007 | E14: 0012 | F14: Rodamiento N311-E-M1 Fag | G14: Pz
... A145: =CONCATENATE(CONCENTRADO!$B145,CONCENTRADO!$C145,CONCENTRADO!$D145,CONCENTRADO!$E145) -> GHR0190001 | B145: G | C145: HR | D145: 019 | E145: 0001 | F145: Arresto Flama Para Regulador Mca Victor Mpdelo Fbr-1 | G145: Pz
A146: =CONCATENATE(CONCENTRADO!$B1877,CONCENTRADO!$C1877,CONCENTRADO!$D1877,CONCENTRADO!$E1877) -> GHR0170027 | B146: G | C146: HR | D146: 008 | E146: 0001 | F146: Ptr Acero a36 Cal 14 De 1 1/2"x1 1/2"x6,00Mts | G146: Pz
A147: =CONCATENATE(CONCENTRADO!$B147,CONCENTRADO!$C147,CONCENTRADO!$D147,CONCENTRADO!$E147) -> GFL0120001 | B147: G | C147: FL | D147: 012 | E147: 0001 | F147: Filtro Perkins 130306360 | G147: Pz
A148: =CONCATENATE(CONCENTRADO!$B148,CONCENTRADO!$C148,CONCENTRADO!$D148,CONCENTRADO!$E148) -> GVV0130001 | B148: G | C148: VV | D148: 013 | E148: 0001 | F148: Valvula De Alivio Nv10-20A | G148: Pz
A149: =CONCATENATE(CONCENTRADO!$B149,CONCENTRADO!$C149,CONCENTRADO!$D149,CONCENTRADO!$E149) -> GVV0080002 | B149: G | C149: VV | D149: 008 | E149: 0002 | F149: Valvula Aguja Mini Niquelada 1/4" 10,000 Psi/ 200 F Ptfe | G149: Pz
A150: =CONCATENATE(CONCENTRADO!$B150,CONCENTRADO!$C150,CONCENTRADO!$D150,CONCENTRADO!$E150) -> GAF0060054 | B150: G | C150: AF | D150: 006 | E150: 0054 | F150: Gpt-Broca Zr Std "X" (0.3970") Cleveland | G150: Pz
A151: =CONCATENATE(CONCENTRADO!$B151,CONCENTRADO!$C151,CONCENTRADO!$D151,CONCENTRADO!$E151) -> GFL0120002 | B151: G | C151: FL | D151: 012 | E151: 0002 | F151: Filtro De Tamiz P169014 | G151: Pz
A152: =CONCATENATE(CONCENTRADO!$B152,CONCENTRADO!$C152,CONCENTRADO!$D152,CONCENTRADO!$E152) -> GAF0060055 | B152: G | C152: AF | D152: 006 | E152: 0055 | F152: Gpt-Broca Zr Std "Z" (0.4130") Cleveland | G152: Pz
A153: =CONCATENATE(CONCENTRADO!$B153,CONCENTRADO!$C153,CONCENTRADO!$D153,CONCENTRADO!$E153) -> GCN0070090 | B153: G | C153: CN | D153: 007 | E153: 0090 | F153: Catarina 41 Paso 35 | G153: Pz
A154: =CONCATENATE(CONCENTRADO!$B154,CONCENTRADO!$C154,CONCENTRADO!$D154,CONCENTRADO!$E154) -> GAF0060056 | B154: G | C154: AF | D154: 006 | E154: 0056 | F154: Gpt-Broca Zr Std "Y" (0.4040") Cleveland | G154: Pz
A155: =CONCATENATE(CONCENTRADO!$B155,CONCENTRADO!$C155,CONCENTRADO!$D155,CONCENTRADO!$E155) -> GAF0060057 | B155: G | C155: AF | D155: 006 | E155: 0057 | F155: Broca Zr Std 1/2" (0.5000") Cleveland | G155: Pz
A156: =CONCATENATE(CONCENTRADO!$B156,CONCENTRADO!$C156,CONCENTRADO!$D156,CONCENTRADO!$E156) -> GAF0060058 | B156: G | C156: AF | D156: 006 | E156: 0058 | F156: Broca Zr Std 1/4"-E (0.2500") Cleveland | G156: Pz
A157: =CONCATENATE(CONCENTRADO!$B157,CONCENTRADO!$C157,CONCENTRADO!$D157,CONCENTRADO!$E157) -> GAF0060059 | B157: G | C157: AF | D157: 006 | E157: 0059 | F157: Broca Zr Std 13/32" (0.4062") Cleveland | G157: Pz
A158: =CONCATENATE(CONCENTRADO!$B158,CONCENTRADO!$C158,CONCENTRADO!$D158,CONCENTRADO!$E158) -> GAF0060060 | B158: G | C158: AF | D158: 006 | E158: 0060 | F158: Broca Zr Std 17/64" (0.2656") Cleveland | G158: Pz
... A222: =CONCATENATE(CONCENTRADO!$B222,CONCENTRADO!$C222,CONCENTRADO!$D222,CONCENTRADO!$E222) -> GLM0090003 | B222: G | C222: LM | D222: 009 | E222: 0003 | F222: Repuestos Mini Rodillo Nylon 4" | G222: Pz
A223: =CONCATENATE(CONCENTRADO!$B244,CONCENTRADO!$C244,CONCENTRADO!$D244,CONCENTRADO!$E244) -> GAF0050087 | B223: G | C223: AF | D223: 005 | E223: 0086 | F223: Cortador (Gpt-Cs-10-01) | G223: Pz
A224: =CONCATENATE(CONCENTRADO!$B224,CONCENTRADO!$C224,CONCENTRADO!$D224,CONCENTRADO!$E224) -> GSL0020016 | B224: G | C224: SL | D224: 002 | E224: 0016 | F224: Carda Circular De Alam. Trenzado A.C 7"-Cara Delgada Austromex | G224: Pz
A225: =CONCATENATE(CONCENTRADO!$B225,CONCENTRADO!$C225,CONCENTRADO!$D225,CONCENTRADO!$E225) -> GSL0020017 | B225: G | C225: SL | D225: 002 | E225: 0017 | F225: Cepillo De Alambre De Acero Inox Mango De 10" Clave 2881 | G225: Pz
A226: =CONCATENATE(CONCENTRADO!$B226,CONCENTRADO!$C226,CONCENTRADO!$D226,CONCENTRADO!$E226) -> GSL0050018 | B226: G | C226: SL | D226: 005 | E226: 0018 | F226: Rueda Flap Rebabeo 150X75X25,4Mm Clave 789 | G226: Pz
A227: =CONCATENATE(CONCENTRADO!$B227,CONCENTRADO!$C227,CONCENTRADO!$D227,CONCENTRADO!$E227) -> GLM0100005 | B227: G | C227: LM | D227: 010 | E227: 0005 | F227: Lija De Agua Carburo De Silico C-99 °80 | G227: Pz
A228: =CONCATENATE(CONCENTRADO!$B228,CONCENTRADO!$C228,CONCENTRADO!$D228,CONCENTRADO!$E228) -> GLM0100006 | B228: G | C228: LM | D228: 010 | E228: 0006 | F228: Lija Oxalum Roja Grano #60 | G228: Pz
A229: =CONCATENATE(CONCENTRADO!$B229,CONCENTRADO!$C229,CONCENTRADO!$D229,CONCENTRADO!$E229) -> GLM0090007 | B229: G | C229: LM | D229: 009 | E229: 0007 | F229: Rodillo De Fibra Con Rosca 110X100X15,9Mm-11 | G229: Pz
A230: =CONCATENATE(CONCENTRADO!$B230,CONCENTRADO!$C230,CONCENTRADO!$D230,CONCENTRADO!$E230) -> GLM0090008 | B230: G | C230: LM | D230: 009 | E230: 0008 | F230: Rodillo De Goma Caucho Con Agarradera 15 Cm (6") | G230: Pz
A231: =CONCATENATE(CONCENTRADO!$B231,CONCENTRADO!$C231,CONCENTRADO!$D231,CONCENTRADO!$E231) -> GLM0090009 | B231: G | C231: LM | D231: 009 | E231: 0009 | F231: Rodillo De Goma Caucho Con Agarradera 20 Cm (8") | G231: Pz
A232: =CONCATENATE(CONCENTRADO!$B232,CONCENTRADO!$C232,CONCENTRADO!$D232,CONCENTRADO!$E232) -> GLM0080010 | B232: G | C232: LM | D232: 008 | E232: 0010 | F232: Brocha Azul De 4" | G232: Pz
A233: =CONCATENATE(CONCENTRADO!$B233,CONCENTRADO!$C233,CONCENTRADO!$D233,CONCENTRADO!$E233) -> GFL0120005 | B233: G | C233: FL | D233: 012 | E233: 0005 | F233: Filtro 557207 | G233: Pz
...
